<body bgcolor="#f0f0f8">
<table width="100%" cellspacing=0 cellpadding=2 border=0 summary="heading">
<tr bgcolor="#6622aa">
<td valign=bottom>&nbsp;<br>
<font color="#ffffff" face="helvetica, arial">&nbsp;<br><big><big><strong>KeyError</strong></big></big></font></td
><td align=right valign=bottom
><font color="#ffffff" face="helvetica, arial">Python 3.7.0: C:\Users\GeoEn\PycharmProjects\ClientNetworkHTTP\venve\Scripts\python.exe<br>Thu Sep 20 09:58:58 2018</font></td></tr></table>
    
<p>A problem occurred in a Python script.  Here is the sequence of
function calls leading up to the error, in the order they occurred.</p>
<table width="100%" cellspacing=0 cellpadding=0 border=0>
<tr><td bgcolor="#d8bbff"><big>&nbsp;</big><a href="file://C:\Users\GeoEn\Desktop\College\School Junior Year\Winter Semester\Networking 466\CSCI_466_Programming_Assignments\cgi-test.py">C:\Users\GeoEn\Desktop\College\School Junior Year\Winter Semester\Networking 466\CSCI_466_Programming_Assignments\cgi-test.py</a> in <strong>&lt;module&gt;</strong>()</td></tr>
<tr><td><font color="#909090"><tt>&nbsp;&nbsp;<small>&nbsp;&nbsp;&nbsp;15</small>&nbsp;&nbsp;&nbsp;&nbsp;&nbsp;print("&lt;H1&gt;Error&lt;/H1&gt;")<br>
</tt></font></td></tr>
<tr><td><font color="#909090"><tt>&nbsp;&nbsp;<small>&nbsp;&nbsp;&nbsp;16</small>&nbsp;&nbsp;&nbsp;&nbsp;&nbsp;print("Please&nbsp;fill&nbsp;in&nbsp;the&nbsp;name&nbsp;and&nbsp;addr&nbsp;fields")<br>
</tt></font></td></tr>
<tr><td><font color="#909090"><tt>&nbsp;&nbsp;<small>&nbsp;&nbsp;&nbsp;17</small>&nbsp;<br>
</tt></font></td></tr>
<tr><td bgcolor="#ffccee"><tt>=&gt;<small>&nbsp;&nbsp;&nbsp;18</small>&nbsp;print("&lt;p&gt;name:",&nbsp;form["name"].value)<br>
</tt></td></tr>
<tr><td><font color="#909090"><tt>&nbsp;&nbsp;<small>&nbsp;&nbsp;&nbsp;19</small>&nbsp;print("&lt;p&gt;addr:",&nbsp;form["addr"].value)<br>
</tt></font></td></tr>
<tr><td><small><font color="#909090"><em>builtin</em> <strong>print</strong>&nbsp;= &lt;built-in function print&gt;, <strong>form</strong>&nbsp;= FieldStorage(None, None, []), ].<strong>value</strong>&nbsp;= []</font></small></td></tr></table>
<table width="100%" cellspacing=0 cellpadding=0 border=0>
<tr><td bgcolor="#d8bbff"><big>&nbsp;</big><a href="file://C:\Users\GeoEn\AppData\Local\Programs\Python\Python37\lib\cgi.py">C:\Users\GeoEn\AppData\Local\Programs\Python\Python37\lib\cgi.py</a> in <strong>__getitem__</strong>(self=FieldStorage(None, None, []), key='name')</td></tr>
<tr><td><font color="#909090"><tt>&nbsp;&nbsp;<small>&nbsp;&nbsp;527</small>&nbsp;&nbsp;&nbsp;&nbsp;&nbsp;&nbsp;&nbsp;&nbsp;&nbsp;&nbsp;&nbsp;&nbsp;&nbsp;if&nbsp;item.name&nbsp;==&nbsp;key:&nbsp;found.append(item)<br>
</tt></font></td></tr>
<tr><td><font color="#909090"><tt>&nbsp;&nbsp;<small>&nbsp;&nbsp;528</small>&nbsp;&nbsp;&nbsp;&nbsp;&nbsp;&nbsp;&nbsp;&nbsp;&nbsp;if&nbsp;not&nbsp;found:<br>
</tt></font></td></tr>
<tr><td bgcolor="#ffccee"><tt>=&gt;<small>&nbsp;&nbsp;529</small>&nbsp;&nbsp;&nbsp;&nbsp;&nbsp;&nbsp;&nbsp;&nbsp;&nbsp;&nbsp;&nbsp;&nbsp;&nbsp;raise&nbsp;KeyError(key)<br>
</tt></td></tr>
<tr><td><font color="#909090"><tt>&nbsp;&nbsp;<small>&nbsp;&nbsp;530</small>&nbsp;&nbsp;&nbsp;&nbsp;&nbsp;&nbsp;&nbsp;&nbsp;&nbsp;if&nbsp;len(found)&nbsp;==&nbsp;1:<br>
</tt></font></td></tr>
<tr><td><font color="#909090"><tt>&nbsp;&nbsp;<small>&nbsp;&nbsp;531</small>&nbsp;&nbsp;&nbsp;&nbsp;&nbsp;&nbsp;&nbsp;&nbsp;&nbsp;&nbsp;&nbsp;&nbsp;&nbsp;return&nbsp;found[0]<br>
</tt></font></td></tr>
<tr><td><small><font color="#909090"><em>builtin</em> <strong>KeyError</strong>&nbsp;= &lt;class 'KeyError'&gt;, <strong>key</strong>&nbsp;= 'name'</font></small></td></tr></table><p><strong>KeyError</strong>: 'name'
<br><tt><small>&nbsp;&nbsp;&nbsp;&nbsp;&nbsp;</small>&nbsp;</tt>args&nbsp;=
('name',)
<br><tt><small>&nbsp;&nbsp;&nbsp;&nbsp;&nbsp;</small>&nbsp;</tt>with_traceback&nbsp;=
&lt;built-in method with_traceback of KeyError object&gt;


<!-- The above is a description of an error in a Python program, formatted
     for a Web browser because the 'cgitb' module was enabled.  In case you
     are not reading this in a Web browser, here is the original traceback:

Traceback (most recent call last):
  File "C:/Users/GeoEn/Desktop/College/School Junior Year/Winter Semester/Networking 466/CSCI_466_Programming_Assignments/cgi-test.py", line 18, in &lt;module&gt;
    print("&lt;p&gt;name:", form["name"].value)
  File "C:\Users\GeoEn\AppData\Local\Programs\Python\Python37\lib\cgi.py", line 529, in __getitem__
    raise KeyError(key)
KeyError: 'name'

-->
